<?xml version="1.0"?>
<robot xmlns:xacro="http://ros.org/wiki/xacro" name="$(arg robot_name)">
  <xacro:arg name="robot_name" default="eduard"/>
  <xacro:arg name="wheel_type" default="unknown"/>
  <xacro:arg name="hardware" default="unknown"/>

  <!-- Chassis -->
  <link name="$(arg robot_name)/base_link">
    <visual>
      <xacro:if value="${'red' in '$(arg robot_name)'}">
        <origin rpy="0 0 1.570796327" xyz="0 0 0"/>
        <geometry>
          <mesh filename="package://edu_robot_control/model/mesh/eduard-red-chassis.dae"/>
        </geometry>
      </xacro:if>
      <xacro:if value="${'green' in '$(arg robot_name)'}">
        <origin rpy="0 0 1.570796327" xyz="0 0 0"/>
        <geometry>
          <mesh filename="package://edu_robot_control/model/mesh/eduard-green-chassis.dae"/>
        </geometry>
      </xacro:if>
      <xacro:if value="${'blue' in '$(arg robot_name)'}">
        <origin rpy="0 0 1.570796327" xyz="0 0 0"/>
        <geometry>
          <mesh filename="package://edu_robot_control/model/mesh/eduard-blue-chassis.dae"/>
        </geometry>
      </xacro:if>            
      <xacro:unless value="${('red' in '$(arg robot_name)') or ('green' in '$(arg robot_name)') or ('blue' in '$(arg robot_name)')}">
        <geometry>
          <mesh filename="package://edu_robot_control/model/mesh/eduard-chassis.dae"/>
        </geometry>
      </xacro:unless>
    </visual>
  </link>

  <!-- Wheels -->
  <!-- Front Left -->
  <link name="$(arg robot_name)/wheel_front_left">
    <visual>
      <geometry>
        <xacro:if value="${'offroad' in '$(arg wheel_type)'}">
          <mesh filename="package://edu_robot_control/model/mesh/offroad-wheel-eduard.dae"/>
        </xacro:if>
        <!-- use mecanum wheels as default -->
        <xacro:unless value="${'offroad' in '$(arg wheel_type)'}">
          <mesh filename="package://edu_robot_control/model/mesh/mecanum-wheel-left-eduard.dae"/>
        </xacro:unless>
      </geometry>
    </visual>
  </link>

  <joint name="$(arg robot_name)/base_to_wheel_front_left" type="continuous">
    <origin rpy="1.570796327 0 0" xyz="0.125 0.163 0.02"/>  
    <parent link="$(arg robot_name)/base_link"/>
    <child link="$(arg robot_name)/wheel_front_left"/>
    <axis xyz="0 0 1"/>
  </joint>

  <!-- Front Right -->
  <link name="$(arg robot_name)/wheel_front_right">
    <visual>
      <geometry>
        <xacro:if value="${'offroad' in '$(arg wheel_type)'}">
          <mesh filename="package://edu_robot_control/model/mesh/offroad-wheel-eduard.dae"/>
        </xacro:if>
        <!-- use mecanum wheels as default -->
        <xacro:unless value="${'offroad' in '$(arg wheel_type)'}">
          <mesh filename="package://edu_robot_control/model/mesh/mecanum-wheel-right-eduard.dae"/>
        </xacro:unless>
      </geometry>
    </visual>
  </link>

  <joint name="$(arg robot_name)/base_to_wheel_front_right" type="continuous">
    <origin rpy="-1.570796327 0 0" xyz="0.125 -0.163 0.02"/>
    <parent link="$(arg robot_name)/base_link"/>
    <child link="$(arg robot_name)/wheel_front_right"/>
    <axis xyz="0 0 1"/>    
  </joint>

  <!-- Rear Left -->
  <link name="$(arg robot_name)/wheel_rear_left">
    <visual>
      <geometry>
        <xacro:if value="${'offroad' in '$(arg wheel_type)'}">
          <mesh filename="package://edu_robot_control/model/mesh/offroad-wheel-eduard.dae"/>
        </xacro:if>
        <!-- use mecanum wheels as default -->
        <xacro:unless value="${'offroad' in '$(arg wheel_type)'}">
          <mesh filename="package://edu_robot_control/model/mesh/mecanum-wheel-right-eduard.dae"/>
        </xacro:unless>
      </geometry>
    </visual>
  </link>

  <joint name="$(arg robot_name)/base_to_wheel_rear_left" type="continuous">
    <origin rpy="1.570796327 0 0" xyz="-0.125 0.163 0.02"/>
    <parent link="$(arg robot_name)/base_link"/>
    <child link="$(arg robot_name)/wheel_rear_left"/>
    <axis xyz="0 0 1"/>    
  </joint>

  <!-- Rear Right -->
  <link name="$(arg robot_name)/wheel_rear_right">
    <visual>
      <geometry>
        <xacro:if value="${'offroad' in '$(arg wheel_type)'}">
          <mesh filename="package://edu_robot_control/model/mesh/offroad-wheel-eduard.dae"/>
        </xacro:if>
        <!-- use mecanum wheels as default -->
        <xacro:unless value="${'offroad' in '$(arg wheel_type)'}">
          <mesh filename="package://edu_robot_control/model/mesh/mecanum-wheel-left-eduard.dae"/>
        </xacro:unless>
      </geometry>
    </visual>
  </link>

  <joint name="$(arg robot_name)/base_to_wheel_rear_right" type="continuous">
    <parent link="$(arg robot_name)/base_link"/>
    <child link="$(arg robot_name)/wheel_rear_right"/>
    <origin rpy="-1.570796327 0 0" xyz="-0.125 -0.163 0.02"/>
    <axis xyz="0 0 1"/>    
  </joint>

  <!-- GPIO Iot2050-->
  <xacro:if value="${'iot2050' in '$(arg hardware)'}">
    <ros2_control name="eduard_iot2050_hardware" type='system'>
      <hardware>
        <plugin>eduart/robot/hardware/iot_shield/Ros2HardwareAdapter</plugin>     
      </hardware>
      <gpio name="x10">
        <command_interface name="pwm_8">
          <param name="period_us">1000</param>
          <param name="pin">8</param>
        </command_interface>
        <state_interface name="pwm_8"/>

        <command_interface name="pwm_9">
          <param name="period_us">1000</param>
          <param name="pin">9</param>
        </command_interface>
        <state_interface name="pwm_9"/>
      </gpio>
      <gpio name="x11">
        <state_interface name="din_2">
          <param name="pin">2</param>
        </state_interface>

        <state_interface name="din_3">
          <param name="pin">3</param>
        </state_interface>

        <state_interface name="din_4">
          <param name="pin">4</param>
        </state_interface>

        <command_interface name="pwm_5">
          <param name="period_us">1000</param>
          <param name="pin">5</param>
        </command_interface>
        <state_interface name="pwm_5"/>

        <command_interface name="pwm_6">
          <param name="period_us">1000</param>
          <param name="pin">6</param>
        </command_interface>
        <state_interface name="pwm_6"/>

        <command_interface name="pwm_7">
          <param name="period_us">1000</param>
          <param name="pin">7</param>
        </command_interface>
        <state_interface name="pwm_7"/>
      </gpio>
      <!-- <gpio name="x12">
        <state_interface name="analog_0">
          <param name="pin">14</param>
        </state_interface>
        <state_interface name="analog_1">
          <param name="pin">15</param>
        </state_interface>
        <state_interface name="analog_2">
          <param name="pin">16</param>
        </state_interface>
        <state_interface name="analog_3">
          <param name="pin">17</param>
        </state_interface>
        <state_interface name="analog_4">
          <param name="pin">18</param>
        </state_interface>
        <state_interface name="analog_5">
          <param name="pin">19</param>
        </state_interface>                
      </gpio> -->
    </ros2_control>
  </xacro:if>
</robot>